<robot name="simple_robot">
    <link name="base_link">
        <visual>
            <origin xyz = "0 0 0"/>
            <geometry>
                <cylinder radius="0.1" length="0.0"/>
            </geometry>
            <material name="blue">
                <color rgba="0.0 0.0 1.0 1.0"/>
            </material>
        </visual>
    </link>

    <link name="link1">
        <visual>
            <origin xyz = "0 0 0.5"/>
            <geometry>
                <cylinder radius="0.1" length="2.0"/>
            </geometry>
            <material name="blue">
                <color rgba="0.0 0.0 1.0 1.0"/>
            </material>
        </visual>
    </link>

    <link name="link2">
        <visual>
            <origin xyz = "0 0 1.0"/>
            <geometry>
                <cylinder radius="0.1" length="2.0"/>
            </geometry>
            <material name="green">
                <color rgba="0.0 1.0 0.0 1.0"/>
            </material>
        </visual>
    </link>

    <joint name="joint1" type="revolute">
        <parent link="base_link"/>
        <child link="link1"/>
        <origin xyz="0 0 0" rpy="0.0 0.0 0.0"/>
        <axis xyz="0.0 1.0 0.0"/>
        <limit lower="-3.14" upper="3.14" effort="5.0" velocity="1.0"/>
    </joint>

    <joint name="joint2" type="revolute">
        <parent link="link1"/>
        <child link="link2"/>
        <origin xyz="0 0 1.5" rpy="0.0 0.0 0.0"/>
        <axis xyz="0.0 1.0 0.0"/>
        <limit lower="-3.14" upper="3.14" effort="5.0" velocity="1.0"/>
    </joint>
</robot>